2020-10-29 22:51:23,499 ERROR: Exception on /class/2/exam/1/topic/1/contribute/question/ [POST] [in c:\users\ponei\github\crowdquiz\venv\lib\site-packages\flask\app.py:1892]
Traceback (most recent call last):
  File "c:\users\ponei\github\crowdquiz\venv\lib\site-packages\flask\app.py", line 2447, in wsgi_app
    response = self.full_dispatch_request()
  File "c:\users\ponei\github\crowdquiz\venv\lib\site-packages\flask\app.py", line 1952, in full_dispatch_request
    rv = self.handle_user_exception(e)
  File "c:\users\ponei\github\crowdquiz\venv\lib\site-packages\flask\app.py", line 1821, in handle_user_exception
    reraise(exc_type, exc_value, tb)
  File "c:\users\ponei\github\crowdquiz\venv\lib\site-packages\flask\_compat.py", line 39, in reraise
    raise value
  File "c:\users\ponei\github\crowdquiz\venv\lib\site-packages\flask\app.py", line 1950, in full_dispatch_request
    rv = self.dispatch_request()
  File "c:\users\ponei\github\crowdquiz\venv\lib\site-packages\flask\app.py", line 1936, in dispatch_request
    return self.view_functions[rule.endpoint](**req.view_args)
  File "c:\users\ponei\github\crowdquiz\venv\lib\site-packages\flask_login\utils.py", line 272, in decorated_view
    return func(*args, **kwargs)
  File "C:\Users\ponei\github\CrowdQuiz\app\routes.py", line 357, in contribute_question
    question_answer_argument = QuestionAnswerArgument(question_answer_id=question_answer.id, argument=form.argument.data)
NameError: name 'QuestionAnswerArgument' is not defined
2020-10-29 22:52:13,924 INFO: CrowdQuiz startup [in C:\Users\ponei\github\CrowdQuiz\app\__init__.py:57]
2020-10-29 22:57:08,948 ERROR: Exception on /class/2/exam/1/topic/1/contribute/question/ [POST] [in c:\users\ponei\github\crowdquiz\venv\lib\site-packages\flask\app.py:1892]
Traceback (most recent call last):
  File "c:\users\ponei\github\crowdquiz\venv\lib\site-packages\flask\app.py", line 2447, in wsgi_app
    response = self.full_dispatch_request()
  File "c:\users\ponei\github\crowdquiz\venv\lib\site-packages\flask\app.py", line 1952, in full_dispatch_request
    rv = self.handle_user_exception(e)
  File "c:\users\ponei\github\crowdquiz\venv\lib\site-packages\flask\app.py", line 1821, in handle_user_exception
    reraise(exc_type, exc_value, tb)
  File "c:\users\ponei\github\crowdquiz\venv\lib\site-packages\flask\_compat.py", line 39, in reraise
    raise value
  File "c:\users\ponei\github\crowdquiz\venv\lib\site-packages\flask\app.py", line 1950, in full_dispatch_request
    rv = self.dispatch_request()
  File "c:\users\ponei\github\crowdquiz\venv\lib\site-packages\flask\app.py", line 1936, in dispatch_request
    return self.view_functions[rule.endpoint](**req.view_args)
  File "c:\users\ponei\github\crowdquiz\venv\lib\site-packages\flask_login\utils.py", line 272, in decorated_view
    return func(*args, **kwargs)
  File "C:\Users\ponei\github\CrowdQuiz\app\routes.py", line 359, in contribute_question
    question_answer_argument = QuestionAnswerArgument(question_answer_id=question_answer.id, argument=form.argument.data)
NameError: name 'QuestionAnswerArgument' is not defined
2020-10-29 22:57:47,905 INFO: CrowdQuiz startup [in C:\Users\ponei\github\CrowdQuiz\app\__init__.py:57]
2020-10-29 22:57:56,009 ERROR: Exception on /class/2/exam/1/topic/1/contribute/question/ [POST] [in c:\users\ponei\github\crowdquiz\venv\lib\site-packages\flask\app.py:1892]
Traceback (most recent call last):
  File "c:\users\ponei\github\crowdquiz\venv\lib\site-packages\flask\app.py", line 2447, in wsgi_app
    response = self.full_dispatch_request()
  File "c:\users\ponei\github\crowdquiz\venv\lib\site-packages\flask\app.py", line 1952, in full_dispatch_request
    rv = self.handle_user_exception(e)
  File "c:\users\ponei\github\crowdquiz\venv\lib\site-packages\flask\app.py", line 1821, in handle_user_exception
    reraise(exc_type, exc_value, tb)
  File "c:\users\ponei\github\crowdquiz\venv\lib\site-packages\flask\_compat.py", line 39, in reraise
    raise value
  File "c:\users\ponei\github\crowdquiz\venv\lib\site-packages\flask\app.py", line 1950, in full_dispatch_request
    rv = self.dispatch_request()
  File "c:\users\ponei\github\crowdquiz\venv\lib\site-packages\flask\app.py", line 1936, in dispatch_request
    return self.view_functions[rule.endpoint](**req.view_args)
  File "c:\users\ponei\github\crowdquiz\venv\lib\site-packages\flask_login\utils.py", line 272, in decorated_view
    return func(*args, **kwargs)
  File "C:\Users\ponei\github\CrowdQuiz\app\routes.py", line 359, in contribute_question
    question_answer_argument = QuestionAnswerArgument(question_answer_id=question_answer.id, argument=form.argument.data)
  File "<string>", line 4, in __init__
  File "c:\users\ponei\github\crowdquiz\venv\lib\site-packages\sqlalchemy\orm\state.py", line 433, in _initialize_instance
    manager.dispatch.init_failure(self, args, kwargs)
  File "c:\users\ponei\github\crowdquiz\venv\lib\site-packages\sqlalchemy\util\langhelpers.py", line 70, in __exit__
    with_traceback=exc_tb,
  File "c:\users\ponei\github\crowdquiz\venv\lib\site-packages\sqlalchemy\util\compat.py", line 182, in raise_
    raise exception
  File "c:\users\ponei\github\crowdquiz\venv\lib\site-packages\sqlalchemy\orm\state.py", line 430, in _initialize_instance
    return manager.original_init(*mixed[1:], **kwargs)
  File "c:\users\ponei\github\crowdquiz\venv\lib\site-packages\sqlalchemy\ext\declarative\base.py", line 840, in _declarative_constructor
    "%r is an invalid keyword argument for %s" % (k, cls_.__name__)
TypeError: 'argument' is an invalid keyword argument for QuestionAnswerArgument
2020-10-29 23:02:36,401 INFO: CrowdQuiz startup [in C:\Users\ponei\github\CrowdQuiz\app\__init__.py:57]
2020-10-29 23:04:37,903 INFO: CrowdQuiz startup [in C:\Users\ponei\github\CrowdQuiz\app\__init__.py:57]
2020-10-29 23:04:46,069 ERROR: Exception on /class/2/exam/1/contribute/ [GET] [in c:\users\ponei\github\crowdquiz\venv\lib\site-packages\flask\app.py:1892]
Traceback (most recent call last):
  File "c:\users\ponei\github\crowdquiz\venv\lib\site-packages\flask\app.py", line 2447, in wsgi_app
    response = self.full_dispatch_request()
  File "c:\users\ponei\github\crowdquiz\venv\lib\site-packages\flask\app.py", line 1952, in full_dispatch_request
    rv = self.handle_user_exception(e)
  File "c:\users\ponei\github\crowdquiz\venv\lib\site-packages\flask\app.py", line 1821, in handle_user_exception
    reraise(exc_type, exc_value, tb)
  File "c:\users\ponei\github\crowdquiz\venv\lib\site-packages\flask\_compat.py", line 39, in reraise
    raise value
  File "c:\users\ponei\github\crowdquiz\venv\lib\site-packages\flask\app.py", line 1950, in full_dispatch_request
    rv = self.dispatch_request()
  File "c:\users\ponei\github\crowdquiz\venv\lib\site-packages\flask\app.py", line 1936, in dispatch_request
    return self.view_functions[rule.endpoint](**req.view_args)
  File "c:\users\ponei\github\crowdquiz\venv\lib\site-packages\flask_login\utils.py", line 272, in decorated_view
    return func(*args, **kwargs)
  File "C:\Users\ponei\github\CrowdQuiz\app\routes.py", line 276, in contribute
    evaluate_questions.append(questions[i])
IndexError: list index out of range
2020-10-29 23:17:48,197 INFO: CrowdQuiz startup [in C:\Users\ponei\github\CrowdQuiz\app\__init__.py:57]
2020-10-29 23:19:17,717 INFO: CrowdQuiz startup [in C:\Users\ponei\github\CrowdQuiz\app\__init__.py:57]
