2020-10-30 14:53:37,141 ERROR: Exception on /class/2/exam/1/topic/1/contribute/ [GET] [in c:\users\ponei\github\crowdquiz\venv\lib\site-packages\flask\app.py:1892]
Traceback (most recent call last):
  File "c:\users\ponei\github\crowdquiz\venv\lib\site-packages\flask\app.py", line 2447, in wsgi_app
    response = self.full_dispatch_request()
  File "c:\users\ponei\github\crowdquiz\venv\lib\site-packages\flask\app.py", line 1952, in full_dispatch_request
    rv = self.handle_user_exception(e)
  File "c:\users\ponei\github\crowdquiz\venv\lib\site-packages\flask\app.py", line 1821, in handle_user_exception
    reraise(exc_type, exc_value, tb)
  File "c:\users\ponei\github\crowdquiz\venv\lib\site-packages\flask\_compat.py", line 39, in reraise
    raise value
  File "c:\users\ponei\github\crowdquiz\venv\lib\site-packages\flask\app.py", line 1950, in full_dispatch_request
    rv = self.dispatch_request()
  File "c:\users\ponei\github\crowdquiz\venv\lib\site-packages\flask\app.py", line 1936, in dispatch_request
    return self.view_functions[rule.endpoint](**req.view_args)
  File "c:\users\ponei\github\crowdquiz\venv\lib\site-packages\flask_login\utils.py", line 272, in decorated_view
    return func(*args, **kwargs)
  File "C:\Users\ponei\github\CrowdQuiz\app\routes.py", line 262, in contribute
    subquery = Question.query(Question.id).filter(Question.user_id != current_user.id).subquery()
TypeError: 'BaseQuery' object is not callable
2020-10-30 14:57:34,387 INFO: CrowdQuiz startup [in C:\Users\ponei\github\CrowdQuiz\app\__init__.py:57]
2020-10-30 14:57:35,871 ERROR: Exception on /class/2/exam/1/topic/1/contribute/ [GET] [in c:\users\ponei\github\crowdquiz\venv\lib\site-packages\flask\app.py:1892]
Traceback (most recent call last):
  File "c:\users\ponei\github\crowdquiz\venv\lib\site-packages\flask\app.py", line 2447, in wsgi_app
    response = self.full_dispatch_request()
  File "c:\users\ponei\github\crowdquiz\venv\lib\site-packages\flask\app.py", line 1952, in full_dispatch_request
    rv = self.handle_user_exception(e)
  File "c:\users\ponei\github\crowdquiz\venv\lib\site-packages\flask\app.py", line 1821, in handle_user_exception
    reraise(exc_type, exc_value, tb)
  File "c:\users\ponei\github\crowdquiz\venv\lib\site-packages\flask\_compat.py", line 39, in reraise
    raise value
  File "c:\users\ponei\github\crowdquiz\venv\lib\site-packages\flask\app.py", line 1950, in full_dispatch_request
    rv = self.dispatch_request()
  File "c:\users\ponei\github\crowdquiz\venv\lib\site-packages\flask\app.py", line 1936, in dispatch_request
    return self.view_functions[rule.endpoint](**req.view_args)
  File "c:\users\ponei\github\crowdquiz\venv\lib\site-packages\flask_login\utils.py", line 272, in decorated_view
    return func(*args, **kwargs)
  File "C:\Users\ponei\github\CrowdQuiz\app\routes.py", line 262, in contribute
    subquery = Question.with_entities(Question.id).filter_by(user_id=current_user.id).subquery()
AttributeError: type object 'Question' has no attribute 'with_entities'
2020-10-30 14:59:38,034 INFO: CrowdQuiz startup [in C:\Users\ponei\github\CrowdQuiz\app\__init__.py:57]
2020-10-30 14:59:39,831 ERROR: Exception on /class/2/exam/1/topic/1/contribute/ [GET] [in c:\users\ponei\github\crowdquiz\venv\lib\site-packages\flask\app.py:1892]
Traceback (most recent call last):
  File "c:\users\ponei\github\crowdquiz\venv\lib\site-packages\flask\app.py", line 2447, in wsgi_app
    response = self.full_dispatch_request()
  File "c:\users\ponei\github\crowdquiz\venv\lib\site-packages\flask\app.py", line 1952, in full_dispatch_request
    rv = self.handle_user_exception(e)
  File "c:\users\ponei\github\crowdquiz\venv\lib\site-packages\flask\app.py", line 1821, in handle_user_exception
    reraise(exc_type, exc_value, tb)
  File "c:\users\ponei\github\crowdquiz\venv\lib\site-packages\flask\_compat.py", line 39, in reraise
    raise value
  File "c:\users\ponei\github\crowdquiz\venv\lib\site-packages\flask\app.py", line 1950, in full_dispatch_request
    rv = self.dispatch_request()
  File "c:\users\ponei\github\crowdquiz\venv\lib\site-packages\flask\app.py", line 1936, in dispatch_request
    return self.view_functions[rule.endpoint](**req.view_args)
  File "c:\users\ponei\github\crowdquiz\venv\lib\site-packages\flask_login\utils.py", line 272, in decorated_view
    return func(*args, **kwargs)
  File "C:\Users\ponei\github\CrowdQuiz\app\routes.py", line 263, in contribute
    subquery = Question.filter_by(user_id=current_user.id).options(load_only(Question.id)).subquery()
AttributeError: type object 'Question' has no attribute 'filter_by'
2020-10-30 14:59:50,634 INFO: CrowdQuiz startup [in C:\Users\ponei\github\CrowdQuiz\app\__init__.py:57]
2020-10-30 15:01:43,873 INFO: CrowdQuiz startup [in C:\Users\ponei\github\CrowdQuiz\app\__init__.py:57]
2020-10-30 15:01:45,099 ERROR: Exception on /class/2/exam/1/topic/1/contribute/ [GET] [in c:\users\ponei\github\crowdquiz\venv\lib\site-packages\flask\app.py:1892]
Traceback (most recent call last):
  File "c:\users\ponei\github\crowdquiz\venv\lib\site-packages\flask\app.py", line 2447, in wsgi_app
    response = self.full_dispatch_request()
  File "c:\users\ponei\github\crowdquiz\venv\lib\site-packages\flask\app.py", line 1952, in full_dispatch_request
    rv = self.handle_user_exception(e)
  File "c:\users\ponei\github\crowdquiz\venv\lib\site-packages\flask\app.py", line 1821, in handle_user_exception
    reraise(exc_type, exc_value, tb)
  File "c:\users\ponei\github\crowdquiz\venv\lib\site-packages\flask\_compat.py", line 39, in reraise
    raise value
  File "c:\users\ponei\github\crowdquiz\venv\lib\site-packages\flask\app.py", line 1950, in full_dispatch_request
    rv = self.dispatch_request()
  File "c:\users\ponei\github\crowdquiz\venv\lib\site-packages\flask\app.py", line 1936, in dispatch_request
    return self.view_functions[rule.endpoint](**req.view_args)
  File "c:\users\ponei\github\crowdquiz\venv\lib\site-packages\flask_login\utils.py", line 272, in decorated_view
    return func(*args, **kwargs)
  File "C:\Users\ponei\github\CrowdQuiz\app\routes.py", line 264, in contribute
    for element in subquery:
TypeError: 'Alias' object is not iterable
2020-10-30 15:04:11,388 INFO: CrowdQuiz startup [in C:\Users\ponei\github\CrowdQuiz\app\__init__.py:57]
2020-10-30 15:06:57,178 INFO: CrowdQuiz startup [in C:\Users\ponei\github\CrowdQuiz\app\__init__.py:57]
2020-10-30 15:07:15,874 INFO: CrowdQuiz startup [in C:\Users\ponei\github\CrowdQuiz\app\__init__.py:57]
2020-10-30 15:18:38,478 INFO: CrowdQuiz startup [in C:\Users\ponei\github\CrowdQuiz\app\__init__.py:57]
2020-10-30 15:19:28,559 INFO: CrowdQuiz startup [in C:\Users\ponei\github\CrowdQuiz\app\__init__.py:57]
