2020-10-21 18:00:09,237 ERROR: Exception on /suggest_subject/new [POST] [in c:\users\ponei\github\crowdquiz\venv\lib\site-packages\flask\app.py:1892]
Traceback (most recent call last):
  File "c:\users\ponei\github\crowdquiz\venv\lib\site-packages\sqlalchemy\engine\base.py", line 1277, in _execute_context
    cursor, statement, parameters, context
  File "c:\users\ponei\github\crowdquiz\venv\lib\site-packages\sqlalchemy\engine\default.py", line 593, in do_execute
    cursor.execute(statement, parameters)
psycopg2.errors.UniqueViolation: duplicate key value violates unique constraint "subject_pkey"
DETAIL:  Key (id)=(2) already exists.


The above exception was the direct cause of the following exception:

Traceback (most recent call last):
  File "c:\users\ponei\github\crowdquiz\venv\lib\site-packages\flask\app.py", line 2447, in wsgi_app
    response = self.full_dispatch_request()
  File "c:\users\ponei\github\crowdquiz\venv\lib\site-packages\flask\app.py", line 1952, in full_dispatch_request
    rv = self.handle_user_exception(e)
  File "c:\users\ponei\github\crowdquiz\venv\lib\site-packages\flask\app.py", line 1821, in handle_user_exception
    reraise(exc_type, exc_value, tb)
  File "c:\users\ponei\github\crowdquiz\venv\lib\site-packages\flask\_compat.py", line 39, in reraise
    raise value
  File "c:\users\ponei\github\crowdquiz\venv\lib\site-packages\flask\app.py", line 1950, in full_dispatch_request
    rv = self.dispatch_request()
  File "c:\users\ponei\github\crowdquiz\venv\lib\site-packages\flask\app.py", line 1936, in dispatch_request
    return self.view_functions[rule.endpoint](**req.view_args)
  File "C:\Users\ponei\github\CrowdQuiz\app\routes.py", line 138, in suggest_new_subject
    db.session.commit()
  File "c:\users\ponei\github\crowdquiz\venv\lib\site-packages\sqlalchemy\orm\scoping.py", line 163, in do
    return getattr(self.registry(), name)(*args, **kwargs)
  File "c:\users\ponei\github\crowdquiz\venv\lib\site-packages\sqlalchemy\orm\session.py", line 1042, in commit
    self.transaction.commit()
  File "c:\users\ponei\github\crowdquiz\venv\lib\site-packages\sqlalchemy\orm\session.py", line 504, in commit
    self._prepare_impl()
  File "c:\users\ponei\github\crowdquiz\venv\lib\site-packages\sqlalchemy\orm\session.py", line 483, in _prepare_impl
    self.session.flush()
  File "c:\users\ponei\github\crowdquiz\venv\lib\site-packages\sqlalchemy\orm\session.py", line 2536, in flush
    self._flush(objects)
  File "c:\users\ponei\github\crowdquiz\venv\lib\site-packages\sqlalchemy\orm\session.py", line 2678, in _flush
    transaction.rollback(_capture_exception=True)
  File "c:\users\ponei\github\crowdquiz\venv\lib\site-packages\sqlalchemy\util\langhelpers.py", line 70, in __exit__
    with_traceback=exc_tb,
  File "c:\users\ponei\github\crowdquiz\venv\lib\site-packages\sqlalchemy\util\compat.py", line 182, in raise_
    raise exception
  File "c:\users\ponei\github\crowdquiz\venv\lib\site-packages\sqlalchemy\orm\session.py", line 2638, in _flush
    flush_context.execute()
  File "c:\users\ponei\github\crowdquiz\venv\lib\site-packages\sqlalchemy\orm\unitofwork.py", line 422, in execute
    rec.execute(self)
  File "c:\users\ponei\github\crowdquiz\venv\lib\site-packages\sqlalchemy\orm\unitofwork.py", line 589, in execute
    uow,
  File "c:\users\ponei\github\crowdquiz\venv\lib\site-packages\sqlalchemy\orm\persistence.py", line 245, in save_obj
    insert,
  File "c:\users\ponei\github\crowdquiz\venv\lib\site-packages\sqlalchemy\orm\persistence.py", line 1136, in _emit_insert_statements
    statement, params
  File "c:\users\ponei\github\crowdquiz\venv\lib\site-packages\sqlalchemy\engine\base.py", line 1011, in execute
    return meth(self, multiparams, params)
  File "c:\users\ponei\github\crowdquiz\venv\lib\site-packages\sqlalchemy\sql\elements.py", line 298, in _execute_on_connection
    return connection._execute_clauseelement(self, multiparams, params)
  File "c:\users\ponei\github\crowdquiz\venv\lib\site-packages\sqlalchemy\engine\base.py", line 1130, in _execute_clauseelement
    distilled_params,
  File "c:\users\ponei\github\crowdquiz\venv\lib\site-packages\sqlalchemy\engine\base.py", line 1317, in _execute_context
    e, statement, parameters, cursor, context
  File "c:\users\ponei\github\crowdquiz\venv\lib\site-packages\sqlalchemy\engine\base.py", line 1511, in _handle_dbapi_exception
    sqlalchemy_exception, with_traceback=exc_info[2], from_=e
  File "c:\users\ponei\github\crowdquiz\venv\lib\site-packages\sqlalchemy\util\compat.py", line 182, in raise_
    raise exception
  File "c:\users\ponei\github\crowdquiz\venv\lib\site-packages\sqlalchemy\engine\base.py", line 1277, in _execute_context
    cursor, statement, parameters, context
  File "c:\users\ponei\github\crowdquiz\venv\lib\site-packages\sqlalchemy\engine\default.py", line 593, in do_execute
    cursor.execute(statement, parameters)
sqlalchemy.exc.IntegrityError: (psycopg2.errors.UniqueViolation) duplicate key value violates unique constraint "subject_pkey"
DETAIL:  Key (id)=(2) already exists.

[SQL: INSERT INTO subject (body, description, approved, user_id) VALUES (%(body)s, %(description)s, %(approved)s, %(user_id)s) RETURNING subject.id]
[parameters: {'body': 'Test2', 'description': 'Just a test', 'approved': False, 'user_id': 1}]
(Background on this error at: http://sqlalche.me/e/13/gkpj)
2020-10-21 18:01:56,593 INFO: CrowdQuiz startup [in C:\Users\ponei\github\CrowdQuiz\app\__init__.py:56]
2020-10-21 18:02:00,340 INFO: CrowdQuiz startup [in C:\Users\ponei\github\CrowdQuiz\app\__init__.py:56]
2020-10-21 18:02:30,019 INFO: CrowdQuiz startup [in C:\Users\ponei\github\CrowdQuiz\app\__init__.py:56]
2020-10-21 18:03:38,335 INFO: CrowdQuiz startup [in C:\Users\ponei\github\CrowdQuiz\app\__init__.py:56]
2020-10-21 18:03:51,716 INFO: CrowdQuiz startup [in C:\Users\ponei\github\CrowdQuiz\app\__init__.py:56]
2020-10-21 18:04:06,995 INFO: CrowdQuiz startup [in C:\Users\ponei\github\CrowdQuiz\app\__init__.py:56]
2020-10-21 18:06:42,935 INFO: CrowdQuiz startup [in C:\Users\ponei\github\CrowdQuiz\app\__init__.py:56]
2020-10-21 20:37:51,319 INFO: CrowdQuiz startup [in C:\Users\ponei\github\CrowdQuiz\app\__init__.py:57]
2020-10-22 01:25:21,969 INFO: CrowdQuiz startup [in C:\Users\ponei\github\CrowdQuiz\app\__init__.py:57]
2020-10-22 01:28:00,180 INFO: CrowdQuiz startup [in C:\Users\ponei\github\CrowdQuiz\app\__init__.py:57]
2020-10-22 01:28:04,746 INFO: CrowdQuiz startup [in C:\Users\ponei\github\CrowdQuiz\app\__init__.py:57]
2020-10-22 01:28:07,818 INFO: CrowdQuiz startup [in C:\Users\ponei\github\CrowdQuiz\app\__init__.py:57]
2020-10-22 01:28:30,769 INFO: CrowdQuiz startup [in C:\Users\ponei\github\CrowdQuiz\app\__init__.py:57]
2020-10-22 01:29:21,238 INFO: CrowdQuiz startup [in C:\Users\ponei\github\CrowdQuiz\app\__init__.py:57]
2020-10-22 01:30:41,463 INFO: CrowdQuiz startup [in C:\Users\ponei\github\CrowdQuiz\app\__init__.py:57]
