2020-10-18 15:03:02,086 ERROR: Exception on /subject/2/new_question [POST] [in c:\users\ponei\github\crowdquiz\venv\lib\site-packages\flask\app.py:1892]
Traceback (most recent call last):
  File "c:\users\ponei\github\crowdquiz\venv\lib\site-packages\flask\app.py", line 2447, in wsgi_app
    response = self.full_dispatch_request()
  File "c:\users\ponei\github\crowdquiz\venv\lib\site-packages\flask\app.py", line 1952, in full_dispatch_request
    rv = self.handle_user_exception(e)
  File "c:\users\ponei\github\crowdquiz\venv\lib\site-packages\flask\app.py", line 1821, in handle_user_exception
    reraise(exc_type, exc_value, tb)
  File "c:\users\ponei\github\crowdquiz\venv\lib\site-packages\flask\_compat.py", line 39, in reraise
    raise value
  File "c:\users\ponei\github\crowdquiz\venv\lib\site-packages\flask\app.py", line 1950, in full_dispatch_request
    rv = self.dispatch_request()
  File "c:\users\ponei\github\crowdquiz\venv\lib\site-packages\flask\app.py", line 1936, in dispatch_request
    return self.view_functions[rule.endpoint](**req.view_args)
  File "c:\users\ponei\github\crowdquiz\venv\lib\site-packages\flask_login\utils.py", line 272, in decorated_view
    return func(*args, **kwargs)
  File "C:\Users\ponei\github\CrowdQuiz\app\routes.py", line 122, in new_question
    if form.validate_on_submit():
  File "c:\users\ponei\github\crowdquiz\venv\lib\site-packages\flask_wtf\form.py", line 100, in validate_on_submit
    return self.is_submitted() and self.validate()
  File "c:\users\ponei\github\crowdquiz\venv\lib\site-packages\wtforms\form.py", line 318, in validate
    return super(Form, self).validate(extra)
  File "c:\users\ponei\github\crowdquiz\venv\lib\site-packages\wtforms\form.py", line 150, in validate
    if not field.validate(self, extra):
  File "c:\users\ponei\github\crowdquiz\venv\lib\site-packages\wtforms\fields\core.py", line 215, in validate
    self.pre_validate(form)
  File "c:\users\ponei\github\crowdquiz\venv\lib\site-packages\wtforms\fields\core.py", line 543, in pre_validate
    values = list(c[0] for c in self.choices)
TypeError: 'NoneType' object is not iterable
2020-10-18 15:04:58,859 INFO: CrowdQuiz startup [in C:\Users\ponei\github\CrowdQuiz\app\__init__.py:56]
2020-10-18 15:05:00,368 ERROR: Exception on /subject/2/new_question [GET] [in c:\users\ponei\github\crowdquiz\venv\lib\site-packages\flask\app.py:1892]
Traceback (most recent call last):
  File "c:\users\ponei\github\crowdquiz\venv\lib\site-packages\flask\app.py", line 2447, in wsgi_app
    response = self.full_dispatch_request()
  File "c:\users\ponei\github\crowdquiz\venv\lib\site-packages\flask\app.py", line 1952, in full_dispatch_request
    rv = self.handle_user_exception(e)
  File "c:\users\ponei\github\crowdquiz\venv\lib\site-packages\flask\app.py", line 1821, in handle_user_exception
    reraise(exc_type, exc_value, tb)
  File "c:\users\ponei\github\crowdquiz\venv\lib\site-packages\flask\_compat.py", line 39, in reraise
    raise value
  File "c:\users\ponei\github\crowdquiz\venv\lib\site-packages\flask\app.py", line 1950, in full_dispatch_request
    rv = self.dispatch_request()
  File "c:\users\ponei\github\crowdquiz\venv\lib\site-packages\flask\app.py", line 1936, in dispatch_request
    return self.view_functions[rule.endpoint](**req.view_args)
  File "c:\users\ponei\github\crowdquiz\venv\lib\site-packages\flask_login\utils.py", line 272, in decorated_view
    return func(*args, **kwargs)
  File "C:\Users\ponei\github\CrowdQuiz\app\routes.py", line 160, in new_question
    form.topics['label'] = 'test'
TypeError: 'NonValidatingSelectMultipleField' object does not support item assignment
2020-10-18 15:10:56,266 INFO: CrowdQuiz startup [in C:\Users\ponei\github\CrowdQuiz\app\__init__.py:56]
2020-10-18 15:21:50,371 INFO: CrowdQuiz startup [in C:\Users\ponei\github\CrowdQuiz\app\__init__.py:56]
