2020-10-23 23:44:18,391 ERROR: Exception on /question/2 [GET] [in c:\users\ponei\github\crowdquiz\venv\lib\site-packages\flask\app.py:1892]
Traceback (most recent call last):
  File "c:\users\ponei\github\crowdquiz\venv\lib\site-packages\sqlalchemy\orm\base.py", line 406, in _entity_descriptor
    return getattr(entity, key)
AttributeError: type object 'Answer' has no attribute 'question_id'

The above exception was the direct cause of the following exception:

Traceback (most recent call last):
  File "c:\users\ponei\github\crowdquiz\venv\lib\site-packages\flask\app.py", line 2447, in wsgi_app
    response = self.full_dispatch_request()
  File "c:\users\ponei\github\crowdquiz\venv\lib\site-packages\flask\app.py", line 1952, in full_dispatch_request
    rv = self.handle_user_exception(e)
  File "c:\users\ponei\github\crowdquiz\venv\lib\site-packages\flask\app.py", line 1821, in handle_user_exception
    reraise(exc_type, exc_value, tb)
  File "c:\users\ponei\github\crowdquiz\venv\lib\site-packages\flask\_compat.py", line 39, in reraise
    raise value
  File "c:\users\ponei\github\crowdquiz\venv\lib\site-packages\flask\app.py", line 1950, in full_dispatch_request
    rv = self.dispatch_request()
  File "c:\users\ponei\github\crowdquiz\venv\lib\site-packages\flask\app.py", line 1936, in dispatch_request
    return self.view_functions[rule.endpoint](**req.view_args)
  File "C:\Users\ponei\github\CrowdQuiz\app\routes.py", line 358, in show_question
    answers = Answer.query.filter_by(question_id=question_id)
  File "c:\users\ponei\github\crowdquiz\venv\lib\site-packages\sqlalchemy\orm\query.py", line 1923, in filter_by
    for key, value in kwargs.items()
  File "c:\users\ponei\github\crowdquiz\venv\lib\site-packages\sqlalchemy\orm\query.py", line 1923, in <listcomp>
    for key, value in kwargs.items()
  File "c:\users\ponei\github\crowdquiz\venv\lib\site-packages\sqlalchemy\orm\base.py", line 412, in _entity_descriptor
    replace_context=err,
  File "c:\users\ponei\github\crowdquiz\venv\lib\site-packages\sqlalchemy\util\compat.py", line 182, in raise_
    raise exception
sqlalchemy.exc.InvalidRequestError: Entity '<class 'app.models.Answer'>' has no property 'question_id'
2020-10-23 23:44:30,850 ERROR: Exception on /class/1/exam/1/ [GET] [in c:\users\ponei\github\crowdquiz\venv\lib\site-packages\flask\app.py:1892]
Traceback (most recent call last):
  File "c:\users\ponei\github\crowdquiz\venv\lib\site-packages\flask\app.py", line 2447, in wsgi_app
    response = self.full_dispatch_request()
  File "c:\users\ponei\github\crowdquiz\venv\lib\site-packages\flask\app.py", line 1952, in full_dispatch_request
    rv = self.handle_user_exception(e)
  File "c:\users\ponei\github\crowdquiz\venv\lib\site-packages\flask\app.py", line 1821, in handle_user_exception
    reraise(exc_type, exc_value, tb)
  File "c:\users\ponei\github\crowdquiz\venv\lib\site-packages\flask\_compat.py", line 39, in reraise
    raise value
  File "c:\users\ponei\github\crowdquiz\venv\lib\site-packages\flask\app.py", line 1950, in full_dispatch_request
    rv = self.dispatch_request()
  File "c:\users\ponei\github\crowdquiz\venv\lib\site-packages\flask\app.py", line 1936, in dispatch_request
    return self.view_functions[rule.endpoint](**req.view_args)
  File "c:\users\ponei\github\crowdquiz\venv\lib\site-packages\flask_login\utils.py", line 272, in decorated_view
    return func(*args, **kwargs)
  File "C:\Users\ponei\github\CrowdQuiz\app\routes.py", line 192, in exam
    return render_template('exam.html', title="Exam", exam=exam, exam_topic_question_counts=zip(exam_topics, question_count))
  File "c:\users\ponei\github\crowdquiz\venv\lib\site-packages\flask\templating.py", line 140, in render_template
    ctx.app,
  File "c:\users\ponei\github\crowdquiz\venv\lib\site-packages\flask\templating.py", line 120, in _render
    rv = template.render(context)
  File "c:\users\ponei\github\crowdquiz\venv\lib\site-packages\jinja2\environment.py", line 1090, in render
    self.environment.handle_exception()
  File "c:\users\ponei\github\crowdquiz\venv\lib\site-packages\jinja2\environment.py", line 832, in handle_exception
    reraise(*rewrite_traceback_stack(source=source))
  File "c:\users\ponei\github\crowdquiz\venv\lib\site-packages\jinja2\_compat.py", line 28, in reraise
    raise value.with_traceback(tb)
  File "C:\Users\ponei\github\CrowdQuiz\app\templates\exam.html", line 1, in top-level template code
    {% extends "base.html" %}
  File "C:\Users\ponei\github\CrowdQuiz\app\templates\base.html", line 1, in top-level template code
    {% extends 'bootstrap_base.html' %}
  File "C:\Users\ponei\github\CrowdQuiz\app\templates\bootstrap_base.html", line 1, in top-level template code
    {% block doc -%}
  File "C:\Users\ponei\github\CrowdQuiz\app\templates\bootstrap_base.html", line 4, in block "doc"
    {%- block html %}
  File "C:\Users\ponei\github\CrowdQuiz\app\templates\bootstrap_base.html", line 22, in block "html"
    {% block body -%}
  File "C:\Users\ponei\github\CrowdQuiz\app\templates\bootstrap_base.html", line 25, in block "body"
    {% block content -%}
  File "C:\Users\ponei\github\CrowdQuiz\app\templates\base.html", line 58, in block "content"
    {% block app_content %}{% endblock %}
  File "C:\Users\ponei\github\CrowdQuiz\app\templates\exam.html", line 45, in block "app_content"
    <a href="{{ url_for('suggested_subjects') }}" class="btn btn-primary">Browse Proposed Topics</a>
  File "c:\users\ponei\github\crowdquiz\venv\lib\site-packages\flask\helpers.py", line 370, in url_for
    return appctx.app.handle_url_build_error(error, endpoint, values)
  File "c:\users\ponei\github\crowdquiz\venv\lib\site-packages\flask\app.py", line 2216, in handle_url_build_error
    reraise(exc_type, exc_value, tb)
  File "c:\users\ponei\github\crowdquiz\venv\lib\site-packages\flask\_compat.py", line 39, in reraise
    raise value
  File "c:\users\ponei\github\crowdquiz\venv\lib\site-packages\flask\helpers.py", line 358, in url_for
    endpoint, values, method=method, force_external=external
  File "c:\users\ponei\github\crowdquiz\venv\lib\site-packages\werkzeug\routing.py", line 2179, in build
    raise BuildError(endpoint, values, method, self)
werkzeug.routing.BuildError: Could not build url for endpoint 'suggested_subjects'. Did you mean 'suggest_new_subject' instead?
