2020-10-21 15:34:08,219 ERROR: Exception on /delete_question/2 [GET] [in c:\users\ponei\github\crowdquiz\venv\lib\site-packages\flask\app.py:1892]
Traceback (most recent call last):
  File "c:\users\ponei\github\crowdquiz\venv\lib\site-packages\flask\app.py", line 2447, in wsgi_app
    response = self.full_dispatch_request()
  File "c:\users\ponei\github\crowdquiz\venv\lib\site-packages\flask\app.py", line 1952, in full_dispatch_request
    rv = self.handle_user_exception(e)
  File "c:\users\ponei\github\crowdquiz\venv\lib\site-packages\flask\app.py", line 1821, in handle_user_exception
    reraise(exc_type, exc_value, tb)
  File "c:\users\ponei\github\crowdquiz\venv\lib\site-packages\flask\_compat.py", line 39, in reraise
    raise value
  File "c:\users\ponei\github\crowdquiz\venv\lib\site-packages\flask\app.py", line 1950, in full_dispatch_request
    rv = self.dispatch_request()
  File "c:\users\ponei\github\crowdquiz\venv\lib\site-packages\flask\app.py", line 1936, in dispatch_request
    return self.view_functions[rule.endpoint](**req.view_args)
  File "c:\users\ponei\github\crowdquiz\venv\lib\site-packages\flask_login\utils.py", line 272, in decorated_view
    return func(*args, **kwargs)
  File "C:\Users\ponei\github\CrowdQuiz\app\routes.py", line 220, in delete_question
    form=form
  File "c:\users\ponei\github\crowdquiz\venv\lib\site-packages\flask\templating.py", line 138, in render_template
    ctx.app.jinja_env.get_or_select_template(template_name_or_list),
  File "c:\users\ponei\github\crowdquiz\venv\lib\site-packages\jinja2\environment.py", line 930, in get_or_select_template
    return self.get_template(template_name_or_list, parent, globals)
  File "c:\users\ponei\github\crowdquiz\venv\lib\site-packages\jinja2\environment.py", line 883, in get_template
    return self._load_template(name, self.make_globals(globals))
  File "c:\users\ponei\github\crowdquiz\venv\lib\site-packages\jinja2\environment.py", line 857, in _load_template
    template = self.loader.load(self, name, globals)
  File "c:\users\ponei\github\crowdquiz\venv\lib\site-packages\jinja2\loaders.py", line 127, in load
    code = environment.compile(source, name, filename)
  File "c:\users\ponei\github\crowdquiz\venv\lib\site-packages\jinja2\environment.py", line 638, in compile
    self.handle_exception(source=source_hint)
  File "c:\users\ponei\github\crowdquiz\venv\lib\site-packages\jinja2\environment.py", line 832, in handle_exception
    reraise(*rewrite_traceback_stack(source=source))
  File "c:\users\ponei\github\crowdquiz\venv\lib\site-packages\jinja2\_compat.py", line 28, in reraise
    raise value.with_traceback(tb)
  File "C:\Users\ponei\github\CrowdQuiz\app\templates\delete_question.html", line 28, in template
    {{ form.cancel("class":"btn btn-primary") }}
jinja2.exceptions.TemplateSyntaxError: expected token ',', got ':'
2020-10-21 15:38:56,641 INFO: CrowdQuiz startup [in C:\Users\ponei\github\CrowdQuiz\app\__init__.py:56]
2020-10-21 15:39:26,471 INFO: CrowdQuiz startup [in C:\Users\ponei\github\CrowdQuiz\app\__init__.py:56]
2020-10-21 15:40:22,111 INFO: CrowdQuiz startup [in C:\Users\ponei\github\CrowdQuiz\app\__init__.py:56]
2020-10-21 15:41:16,261 INFO: CrowdQuiz startup [in C:\Users\ponei\github\CrowdQuiz\app\__init__.py:56]
2020-10-21 15:50:01,431 INFO: CrowdQuiz startup [in C:\Users\ponei\github\CrowdQuiz\app\__init__.py:56]
2020-10-21 16:39:57,602 INFO: CrowdQuiz startup [in C:\Users\ponei\github\CrowdQuiz\app\__init__.py:56]
2020-10-21 16:41:26,481 INFO: CrowdQuiz startup [in C:\Users\ponei\github\CrowdQuiz\app\__init__.py:56]
2020-10-21 16:41:28,916 ERROR: Exception on /admin [GET] [in c:\users\ponei\github\crowdquiz\venv\lib\site-packages\flask\app.py:1892]
Traceback (most recent call last):
  File "c:\users\ponei\github\crowdquiz\venv\lib\site-packages\flask\app.py", line 2447, in wsgi_app
    response = self.full_dispatch_request()
  File "c:\users\ponei\github\crowdquiz\venv\lib\site-packages\flask\app.py", line 1952, in full_dispatch_request
    rv = self.handle_user_exception(e)
  File "c:\users\ponei\github\crowdquiz\venv\lib\site-packages\flask\app.py", line 1821, in handle_user_exception
    reraise(exc_type, exc_value, tb)
  File "c:\users\ponei\github\crowdquiz\venv\lib\site-packages\flask\_compat.py", line 39, in reraise
    raise value
  File "c:\users\ponei\github\crowdquiz\venv\lib\site-packages\flask\app.py", line 1950, in full_dispatch_request
    rv = self.dispatch_request()
  File "c:\users\ponei\github\crowdquiz\venv\lib\site-packages\flask\app.py", line 1936, in dispatch_request
    return self.view_functions[rule.endpoint](**req.view_args)
  File "c:\users\ponei\github\crowdquiz\venv\lib\site-packages\flask_login\utils.py", line 272, in decorated_view
    return func(*args, **kwargs)
  File "C:\Users\ponei\github\CrowdQuiz\app\routes.py", line 27, in admin
    questions = Question.query.filter_by(user_id=user.id).order_by(Question.id.desc()).limit(20)
AttributeError: 'function' object has no attribute 'id'
2020-10-21 16:42:01,664 INFO: CrowdQuiz startup [in C:\Users\ponei\github\CrowdQuiz\app\__init__.py:56]
2020-10-21 16:42:19,836 INFO: CrowdQuiz startup [in C:\Users\ponei\github\CrowdQuiz\app\__init__.py:56]
2020-10-21 16:42:33,208 INFO: CrowdQuiz startup [in C:\Users\ponei\github\CrowdQuiz\app\__init__.py:56]
2020-10-21 16:42:58,870 INFO: CrowdQuiz startup [in C:\Users\ponei\github\CrowdQuiz\app\__init__.py:56]
2020-10-21 16:43:30,566 INFO: CrowdQuiz startup [in C:\Users\ponei\github\CrowdQuiz\app\__init__.py:56]
2020-10-21 16:43:43,677 INFO: CrowdQuiz startup [in C:\Users\ponei\github\CrowdQuiz\app\__init__.py:56]
2020-10-21 16:43:57,642 INFO: CrowdQuiz startup [in C:\Users\ponei\github\CrowdQuiz\app\__init__.py:56]
2020-10-21 16:45:19,053 INFO: CrowdQuiz startup [in C:\Users\ponei\github\CrowdQuiz\app\__init__.py:56]
2020-10-21 16:45:51,106 INFO: CrowdQuiz startup [in C:\Users\ponei\github\CrowdQuiz\app\__init__.py:56]
2020-10-21 16:46:04,169 INFO: CrowdQuiz startup [in C:\Users\ponei\github\CrowdQuiz\app\__init__.py:56]
2020-10-21 16:47:33,540 INFO: CrowdQuiz startup [in C:\Users\ponei\github\CrowdQuiz\app\__init__.py:56]
2020-10-21 16:47:34,658 ERROR: Exception on /index [GET] [in c:\users\ponei\github\crowdquiz\venv\lib\site-packages\flask\app.py:1892]
Traceback (most recent call last):
  File "c:\users\ponei\github\crowdquiz\venv\lib\site-packages\flask\app.py", line 2447, in wsgi_app
    response = self.full_dispatch_request()
  File "c:\users\ponei\github\crowdquiz\venv\lib\site-packages\flask\app.py", line 1952, in full_dispatch_request
    rv = self.handle_user_exception(e)
  File "c:\users\ponei\github\crowdquiz\venv\lib\site-packages\flask\app.py", line 1821, in handle_user_exception
    reraise(exc_type, exc_value, tb)
  File "c:\users\ponei\github\crowdquiz\venv\lib\site-packages\flask\_compat.py", line 39, in reraise
    raise value
  File "c:\users\ponei\github\crowdquiz\venv\lib\site-packages\flask\app.py", line 1950, in full_dispatch_request
    rv = self.dispatch_request()
  File "c:\users\ponei\github\crowdquiz\venv\lib\site-packages\flask\app.py", line 1936, in dispatch_request
    return self.view_functions[rule.endpoint](**req.view_args)
  File "C:\Users\ponei\github\CrowdQuiz\app\routes.py", line 22, in index
    return render_template('index.html', title='Home', subjects=subject, topics=topics, subjectcounts=questionCount)
  File "c:\users\ponei\github\crowdquiz\venv\lib\site-packages\flask\templating.py", line 140, in render_template
    ctx.app,
  File "c:\users\ponei\github\crowdquiz\venv\lib\site-packages\flask\templating.py", line 120, in _render
    rv = template.render(context)
  File "c:\users\ponei\github\crowdquiz\venv\lib\site-packages\jinja2\environment.py", line 1090, in render
    self.environment.handle_exception()
  File "c:\users\ponei\github\crowdquiz\venv\lib\site-packages\jinja2\environment.py", line 832, in handle_exception
    reraise(*rewrite_traceback_stack(source=source))
  File "c:\users\ponei\github\crowdquiz\venv\lib\site-packages\jinja2\_compat.py", line 28, in reraise
    raise value.with_traceback(tb)
  File "C:\Users\ponei\github\CrowdQuiz\app\templates\index.html", line 1, in top-level template code
    {% extends "base.html" %}
  File "c:\users\ponei\github\crowdquiz\venv\lib\site-packages\jinja2\environment.py", line 832, in handle_exception
    reraise(*rewrite_traceback_stack(source=source))
  File "c:\users\ponei\github\crowdquiz\venv\lib\site-packages\jinja2\_compat.py", line 28, in reraise
    raise value.with_traceback(tb)
  File "C:\Users\ponei\github\CrowdQuiz\app\templates\base.html", line 28, in template
    {% current_user.admin %}
jinja2.exceptions.TemplateSyntaxError: Encountered unknown tag 'current_user'. Jinja was looking for the following tags: 'endif'. The innermost block that needs to be closed is 'if'.
2020-10-21 16:47:49,043 INFO: CrowdQuiz startup [in C:\Users\ponei\github\CrowdQuiz\app\__init__.py:56]
2020-10-21 16:48:05,985 INFO: CrowdQuiz startup [in C:\Users\ponei\github\CrowdQuiz\app\__init__.py:56]
2020-10-21 16:49:40,087 INFO: CrowdQuiz startup [in C:\Users\ponei\github\CrowdQuiz\app\__init__.py:56]
2020-10-21 16:49:50,569 INFO: CrowdQuiz startup [in C:\Users\ponei\github\CrowdQuiz\app\__init__.py:56]
